Workbook
Name RepsList: #REF!
Name Rest_SecondsList: #REF!
Name SetsList: #REF!

Sheet DATA
A1: Sets | B1: Reps | C1: Rest_Seconds | E1: Quadriceps | F1: Glutes_Hamstrings | G1: Calves | H1: Chest | I1: Back | J1: Shoulders | K1: Triceps | L1: Biceps | M1: Abs | N1: Other
A2: 1 | B2: 4 - 6 | C2: 30 | E2: Barbell Box Squat | F2: Barbell Deadlift | G2: Barbell Calf Raise | H2: Barbell Decline Bench Press | I2: Barbell Bent Over Row | J2: Barbell Front Raise | K2: Barbell Close-Grip Bench Press | L2: Barbell Close-Grip Biceps Curl | M2: Barbell Plate Ab Twist | N2: Barbell Wrist Curl
A3: 2 | B3: 6 - 8 | C3: 60 | E3: Barbell Bulgarian Split-Squat | F3: Barbell Deadlifts from Blocks | G3: Dumbbell Calf Raise | H3: Barbell Flat Bench Press | I3: Barbell Chest-Supported T-Bar Row | J3: Barbell One-Arm Linear Jammer | K3: Barbell Decline Bench Triceps Extension | L3: Barbell Concentration Biceps Curl | M3: Body Weight Ab Crunch | N3: Dumbbell Wrist Curl
A4: 3 | B4: 8 - 10 | C4: 90 | E4: Barbell Front Squat | F4: Barbell Deadlifts from Deficit | G4: Machine Calf Extension (Seated) | H4: Barbell Incline Bench Press | I4: Barbell Incline Bench Row | J4: Barbell Push Press | K4: Barbell Flat Bench Triceps Extension | L4: Barbell Preacher Biceps Curl | M4: Body Weight Hanging Leg Raise | N4: Neck Curl
A5: 4 | B5: 8 - 12 | C5: 120 | E5: Barbell Jump Squat | F5: Barbell Glute Bridge | G5: Machine Calf Raise | H5: Body Weight Decline Push-Up | I5: Barbell One-Arm Row | J5: Barbell Seated Shoulder Press | K5: Barbell Incline Bench Triceps Extension | L5: Barbell Regular-Grip Biceps Curl | M5: Body Weight Plank | N5: Neck Extension
A6: 5 | B6: 12 - 15 | C6: 150 | E6: Barbell Squat | F6: Barbell Hip Thrust | G6: Machine Leg Press Calf Extension (Seated/Laying) | H6: Body Weight Dip (Chest Variation) | I6: Barbell Pendlay Row | J6: Barbell Standing Shoulder Press | K6: Barbell Overhead Triceps Extension | L6: Barbell Reverse-Grip Biceps Curl | M6: Dumbbell Ab Twist | N6: ITB release via Foam roller
A7: 6 | B7: 15 - 20 | C7: 180 | E7: Barbell Standing Lunge | F7: Barbell Romanian Deadlift | G7: Single Leg Seated Calf Raise | H7: Body Weight Incline Push-Up | I7: Barbell Reverse Grip Bent Over | J7: Barbell Upright Row | K7: Body Weight Bench Dip | L7: Barbell Wide-Grip Biceps Curl | M7: Machine Ab Crunch | N7: TFL release via Trigger ball
A8: 7 | B8: 20 - 25 | C8: 240 | E8: Barbell Step Up | F8: Barbell Stiff-Legged Deadlift | H8: Body Weight Push-Up | I8: Barbell Shrug | J8: Body Weight Handstand Push-Up | K8: Body Weight Dips (Triceps Variation) | L8: Body Weight Chin-Up | M8: Weighted Hanging Leg Raise
A9: 8 | B9: 25 - 30 | C9: 300 | E9: Barbell Walking Lunge | F9: Barbell Sumo Deadlift | H9: Cable Chest Press (Seated) | I9: Barbell T-Bar Row | J9: Body Weight Pike Push-Up | K9: Cable Decline Bench Triceps Extension | L9: Cable Bar Biceps Curl | M9: Weighted Plank
E10: Body Weight Bulgarian Split-Squat | F10: Body Weight Glute-Ham Raise | H10: Cable Chest Press (Standing) | I10: Body Weight Back Extension | J10: Cable Face Pull | K10: Cable Flat Bench Triceps Extension | L10: Cable Incline Bench Biceps Curl
E11: Body Weight Pistol Squat | F11: Cable One-Legged Kickback | H11: Cable Crossover | I11: Body Weight Inverted Row | J11: Cable Front Raise | K11: Cable Incline Bench Triceps Extension | L11: Cable One-Arm Biceps Curl
E12: Body Weight Squat | F12: Cable Pull Through | H12: Cable Crossover (High Angle) | I12: Body Weight Pull-Up | J12: Cable Lateral Raise | K12: Cable One-Arm Overhead Triceps Extension | L12: Cable Overhead Curl
E13: Body Weight Standing Lunge | F13: Dumbbell Glute Bridge | H13: Cable Crossover (Low Angle) | I13: Cable Narrow-Grip Lat Pull-Down | J13: Cable Rear Delt Fly | K13: Cable Overhead Triceps Extension | L13: Cable Rope Biceps Curl
E14: Body Weight Step Up | F14: Dumbbell Hip Thrust | H14: Cable Flat Bench Fly | I14: Cable One-Arm Lat Pull-Down | J14: Cable Shoulder Press (Seated) | K14: Cable Reverse-Grip Triceps Push-Down | L14: Dumbbell Alternate Biceps Curl
E15: Body Weight Walking Lunge | F15: Dumbbell Romanian Deadlift | H15: Cable Incline Bench Fly | I15: Cable One-Arm Row (Seated) | J15: Cable Standing Shoulder Press (Standing) | K15: Cable Rope Triceps Push-Down | L15: Dumbbell Concentration Biceps Curl
E16: Dumbbell Body Weight Squat | F16: Dumbbell Stiff-Legged Deadlift | H16: Cable Incline Bench Press | I16: Cable Reverse-Grip Lat Pull-Down | J16: Cable Upright Row | K16: Cable Straight-Bar Triceps Push-Down | L16: Dumbbell Hammer Biceps Curl
E17: Dumbbell Bulgarian Split-Squat | F17: Machine Glute-Ham Raise | H17: Dumbbell Decline Bench Fly | I17: Cable Row (Seated) | J17: Dumbbell Arnold Press | K17: Cable Triceps Kickback | L17: Dumbbell Incline Bench Biceps Curl
E18: Dumbbell Goblet Squat | F18: Machine Laying Leg Curl | H18: Dumbbell Decline Bench Press | I18: Cable Straight-Arm Pull-Down | J18: Dumbbell Front Raise | K18: Cable V-Bar Triceps Push-Down | L18: Dumbbell One-Arm Biceps Curl
E19: Dumbbell Standing Lunge | F19: Machine Reverse Hyperextension | H19: Dumbbell Flat Bench Fly | I19: Cable V-Bar Lat Pull-Down | J19: Dumbbell One-Arm Lateral Raise | K19: Dumbbell Bent Over Triceps Extension | L19: Dumbbell Preacher Biceps Curl
E20: Dumbbell Step Up | F20: Machine Seated Leg Curl | H20: Dumbbell Flat Bench Press | I20: Cable Wide-Grip Lat Pull-Down | J20: Dumbbell Rear Delt Raise | K20: Dumbbell Close-Grip Bench Press | L20: Dumbbell Reverse-Grip Biceps Curl
E21: Dumbbell Walking Lunge | F21: Glute Bridge | H21: Dumbbell Incline Bench Fly | I21: Dumbbell Bent Over Row | J21: Dumbbell Reverse Fly | K21: Dumbbell Decline Bench Triceps Extension | L21: Dumbbell Reverse-Grip Biceps Curl
... E24: Machine Leg Press | F24: Double Leg Hamstring Bridge | H24: Machine Butterfly | I24: Dumbbell Reverse Grip Bent Over | J24: Dumbbell Standing One-Arm Press | K24: Dumbbell One-Arm Overhead Triceps Extension | L24: Machine Preacher Biceps Curl
E25: Machine Seated Leg Press | H25: Machine Chest Press | I25: Dumbbell Shrug | J25: Dumbbell Standing Shoulder Press | K25: Dumbbell Overhead Triceps Extension | L25: Weighted Chin-Up
E26: Machine Single-Leg Press | H26: Machine Decline Chest Press | I26: Machine Assisted Pull-Up | J26: Dumbbell Upright Row | K26: Dumbbell Triceps Kickback
E27: Hip Ab/Adduction (Pulse) | H27: Machine Incline Chest Press | I27: Machine Back Extension | J27: Machine Lateral Raise | K27: Machine Assisted Dips (Triceps Variation)
H28: Smith Machine Bench Press | I28: Machine Chest Supported Row | J28: Machine Reverse Fly | K28: Machine Triceps Extension
H29: Smith Machine Decline Chest Press | I29: Machine Iso Row | J29: Machine Shoulder Press | K29: Smith Machine Close-Grip Bench Press
H30: Smith Machine Incline Bench Press | I30: Machine Shrug | J30: Machine Upright Row | K30: Weighted Bench Dip
H31: Weighted Decline Push-Up | I31: Smith Machine Bent Over Row | J31: Smith Machine Shoulder Press | K31: Weighted Dips (Triceps Variation)
H32: Weighted Dip (Chest Variation) | I32: Weighted Pull-Up
H33: Weighted Incline Push-Up
H34: Weighted Push-Up

Sheet Performance Tracker
C1: Volume Tracker | P1: Strength Tracker
C2: Week 1 | D2: Week 2 | E2: Week 3 | F2: Week 4 | G2: Week 5 | H2: Week 6 | I2: Week 7 | J2: Week 8 | K2: Week 9 | L2: Week 10 | M2: Week 11 | N2: Week 12 | P2: Week 1 | Q2: Week 2 | R2: Week 3 | S2: Week 4 | T2: Week 5 | U2: Week 6 | V2: Week 7 | W2: Week 8 | X2: Week 9 | Y2: Week 10 | Z2: Week 11 | AA2: Week 12
A3: Day 1 | B3: =IF('Workout Setup'!C2=0,"",'Workout Setup'!C2) -> Barbell Glute Bridge | C3: ='Week 1'!I2 | D3: ='Week 2'!I2 | E3: ='Week 3'!I2 | F3: ='Week 4'!I2 | G3: ='Week 5'!I2 | H3: ='Week 6'!I2 | I3: ='Week 7'!I2 | J3: ='Week 8'!I2 | K3: ='Week 9'!I2 | L3: ='Week 10'!I2 | M3: ='Week 11'!I2 | N3: ='Week 12'!I2 | P3: ='Week 1'!G2 -> 0 | Q3: ='Week 2'!G2 -> 0 | R3: ='Week 3'!G2 -> 0 | S3: ='Week 4'!G2 -> 0 | T3: ='Week 5'!G2 -> 0 | U3: ='Week 6'!G2 -> 0 | V3: ='Week 7'!G2 -> 0 | W3: ='Week 8'!G2 -> 0 | X3: ='Week 9'!G2 -> 0 | Y3: ='Week 10'!G2 -> 0 | Z3: ='Week 11'!G2 -> 0 | AA3: ='Week 12'!G2 -> 0
C4: - | D4: =IFERROR((D3-C3)/C3,"-") -> - | E4: =IFERROR((E3-D3)/D3,"-") -> - | F4: =IFERROR((F3-E3)/E3,"-") -> - | G4: =IFERROR((G3-F3)/F3,"-") -> - | H4: =IFERROR((H3-G3)/G3,"-") -> - | I4: =IFERROR((I3-H3)/H3,"-") -> - | J4: =IFERROR((J3-I3)/I3,"-") -> - | K4: =IFERROR((K3-J3)/J3,"-") -> - | ... N4: =IFERROR((N3-M3)/M3,"-") -> - | P4: - | Q4: =IFERROR((Q3-P3)/P3,"-") -> - | R4: =IFERROR((R3-Q3)/Q3,"-") -> - | S4: =IFERROR((S3-R3)/R3,"-") -> - | T4: =IFERROR((T3-S3)/S3,"-") -> - | U4: =IFERROR((U3-T3)/T3,"-") -> - | V4: =IFERROR((V3-U3)/U3,"-") -> - | W4: =IFERROR((W3-V3)/V3,"-") -> - | X4: =IFERROR((X3-W3)/W3,"-") -> - | ... AA4: =IFERROR((AA3-Z3)/Z3,"-") -> -
B5: =IF('Workout Setup'!C3=0,"",'Workout Setup'!C3) -> Barbell Hip Thrust | C5: ='Week 1'!I3 | D5: ='Week 2'!I3 | E5: ='Week 3'!I3 | F5: ='Week 4'!I3 | G5: ='Week 5'!I3 | H5: ='Week 6'!I3 | I5: ='Week 7'!I3 | J5: ='Week 8'!I3 | K5: ='Week 9'!I3 | L5: ='Week 10'!I3 | M5: ='Week 11'!I3 | N5: ='Week 12'!I3 | P5: ='Week 1'!G3 -> 0 | Q5: ='Week 2'!G3 -> 0 | R5: ='Week 3'!G3 -> 0 | S5: ='Week 4'!G3 -> 0 | T5: ='Week 5'!G3 -> 0 | U5: ='Week 6'!G3 -> 0 | V5: ='Week 7'!G3 -> 0 | W5: ='Week 8'!G3 -> 0 | X5: ='Week 9'!G3 -> 0 | Y5: ='Week 10'!G3 -> 0 | Z5: ='Week 11'!G3 -> 0 | AA5: ='Week 12'!G3 -> 0
C6: - | D6: =IFERROR((D5-C5)/C5,"-") -> - | E6: =IFERROR((E5-D5)/D5,"-") -> - | F6: =IFERROR((F5-E5)/E5,"-") -> - | G6: =IFERROR((G5-F5)/F5,"-") -> - | H6: =IFERROR((H5-G5)/G5,"-") -> - | I6: =IFERROR((I5-H5)/H5,"-") -> - | J6: =IFERROR((J5-I5)/I5,"-") -> - | K6: =IFERROR((K5-J5)/J5,"-") -> - | ... N6: =IFERROR((N5-M5)/M5,"-") -> - | P6: - | Q6: =IFERROR((Q5-P5)/P5,"-") -> - | R6: =IFERROR((R5-Q5)/Q5,"-") -> - | S6: =IFERROR((S5-R5)/R5,"-") -> - | T6: =IFERROR((T5-S5)/S5,"-") -> - | U6: =IFERROR((U5-T5)/T5,"-") -> - | V6: =IFERROR((V5-U5)/U5,"-") -> - | W6: =IFERROR((W5-V5)/V5,"-") -> - | X6: =IFERROR((X5-W5)/W5,"-") -> - | ... AA6: =IFERROR((AA5-Z5)/Z5,"-") -> -
B7: =IF('Workout Setup'!C4=0,"",'Workout Setup'!C4) -> Cable One-Legged Kickback | C7: ='Week 1'!I4 | D7: ='Week 2'!I4 | E7: ='Week 3'!I4 | F7: ='Week 4'!I4 | G7: ='Week 5'!I4 | H7: ='Week 6'!I4 | I7: ='Week 7'!I4 | J7: ='Week 8'!I4 | K7: ='Week 9'!I4 | L7: ='Week 10'!I4 | M7: ='Week 11'!I4 | N7: ='Week 12'!I4 | P7: ='Week 1'!G4 -> 0 | Q7: ='Week 2'!G4 -> 0 | R7: ='Week 3'!G4 -> 0 | S7: ='Week 4'!G4 -> 0 | T7: ='Week 5'!G4 -> 0 | U7: ='Week 6'!G4 -> 0 | V7: ='Week 7'!G4 -> 0 | W7: ='Week 8'!G4 -> 0 | X7: ='Week 9'!G4 -> 0 | Y7: ='Week 10'!G4 -> 0 | Z7: ='Week 11'!G4 -> 0 | AA7: ='Week 12'!G4 -> 0
C8: - | D8: =IFERROR((D7-C7)/C7,"-") -> - | E8: =IFERROR((E7-D7)/D7,"-") -> - | F8: =IFERROR((F7-E7)/E7,"-") -> - | G8: =IFERROR((G7-F7)/F7,"-") -> - | H8: =IFERROR((H7-G7)/G7,"-") -> - | I8: =IFERROR((I7-H7)/H7,"-") -> - | J8: =IFERROR((J7-I7)/I7,"-") -> - | K8: =IFERROR((K7-J7)/J7,"-") -> - | ... N8: =IFERROR((N7-M7)/M7,"-") -> - | P8: - | Q8: =IFERROR((Q7-P7)/P7,"-") -> - | R8: =IFERROR((R7-Q7)/Q7,"-") -> - | S8: =IFERROR((S7-R7)/R7,"-") -> - | T8: =IFERROR((T7-S7)/S7,"-") -> - | U8: =IFERROR((U7-T7)/T7,"-") -> - | V8: =IFERROR((V7-U7)/U7,"-") -> - | W8: =IFERROR((W7-V7)/V7,"-") -> - | X8: =IFERROR((X7-W7)/W7,"-") -> - | ... AA8: =IFERROR((AA7-Z7)/Z7,"-") -> -
B9: =IF('Workout Setup'!C5=0,"",'Workout Setup'!C5) -> Barbell Squat | C9: ='Week 1'!I5 | D9: ='Week 2'!I5 | E9: ='Week 3'!I5 | F9: ='Week 4'!I5 | G9: ='Week 5'!I5 | H9: ='Week 6'!I5 | I9: ='Week 7'!I5 | J9: ='Week 8'!I5 | K9: ='Week 9'!I5 | L9: ='Week 10'!I5 | M9: ='Week 11'!I5 | N9: ='Week 12'!I5 | P9: ='Week 1'!G5 -> 0 | Q9: ='Week 2'!G5 -> 0 | R9: ='Week 3'!G5 -> 0 | S9: ='Week 4'!G5 -> 0 | T9: ='Week 5'!G5 -> 0 | U9: ='Week 6'!G5 -> 0 | V9: ='Week 7'!G5 -> 0 | W9: ='Week 8'!G5 -> 0 | X9: ='Week 9'!G5 -> 0 | Y9: ='Week 10'!G5 -> 0 | Z9: ='Week 11'!G5 -> 0 | AA9: ='Week 12'!G5 -> 0
C10: - | D10: =IFERROR((D9-C9)/C9,"-") -> - | E10: =IFERROR((E9-D9)/D9,"-") -> - | F10: =IFERROR((F9-E9)/E9,"-") -> - | G10: =IFERROR((G9-F9)/F9,"-") -> - | H10: =IFERROR((H9-G9)/G9,"-") -> - | I10: =IFERROR((I9-H9)/H9,"-") -> - | J10: =IFERROR((J9-I9)/I9,"-") -> - | K10: =IFERROR((K9-J9)/J9,"-") -> - | ... N10: =IFERROR((N9-M9)/M9,"-") -> - | P10: - | Q10: =IFERROR((Q9-P9)/P9,"-") -> - | R10: =IFERROR((R9-Q9)/Q9,"-") -> - | S10: =IFERROR((S9-R9)/R9,"-") -> - | T10: =IFERROR((T9-S9)/S9,"-") -> - | U10: =IFERROR((U9-T9)/T9,"-") -> - | V10: =IFERROR((V9-U9)/U9,"-") -> - | W10: =IFERROR((W9-V9)/V9,"-") -> - | X10: =IFERROR((X9-W9)/W9,"-") -> - | ... AA10: =IFERROR((AA9-Z9)/Z9,"-") -> -
B11: =IF('Workout Setup'!C6=0,"",'Workout Setup'!C6) -> Machine Laying Leg Press | C11: ='Week 1'!I6 | D11: ='Week 2'!I6 | E11: ='Week 3'!I6 | F11: ='Week 4'!I6 | G11: ='Week 5'!I6 | H11: ='Week 6'!I6 | I11: ='Week 7'!I6 | J11: ='Week 8'!I6 | K11: ='Week 9'!I6 | L11: ='Week 10'!I6 | M11: ='Week 11'!I6 | N11: ='Week 12'!I6 | P11: ='Week 1'!G6 -> 0 | Q11: ='Week 2'!G6 -> 0 | R11: ='Week 3'!G6 -> 0 | S11: ='Week 4'!G6 -> 0 | T11: ='Week 5'!G6 -> 0 | U11: ='Week 6'!G6 -> 0 | V11: ='Week 7'!G6 -> 0 | W11: ='Week 8'!G6 -> 0 | X11: ='Week 9'!G6 -> 0 | Y11: ='Week 10'!G6 -> 0 | Z11: ='Week 11'!G6 -> 0 | AA11: ='Week 12'!G6 -> 0
C12: - | D12: =IFERROR((D11-C11)/C11,"-") -> - | E12: =IFERROR((E11-D11)/D11,"-") -> - | F12: =IFERROR((F11-E11)/E11,"-") -> - | G12: =IFERROR((G11-F11)/F11,"-") -> - | H12: =IFERROR((H11-G11)/G11,"-") -> - | I12: =IFERROR((I11-H11)/H11,"-") -> - | J12: =IFERROR((J11-I11)/I11,"-") -> - | K12: =IFERROR((K11-J11)/J11,"-") -> - | ... N12: =IFERROR((N11-M11)/M11,"-") -> - | P12: - | Q12: =IFERROR((Q11-P11)/P11,"-") -> - | R12: =IFERROR((R11-Q11)/Q11,"-") -> - | S12: =IFERROR((S11-R11)/R11,"-") -> - | T12: =IFERROR((T11-S11)/S11,"-") -> - | U12: =IFERROR((U11-T11)/T11,"-") -> - | V12: =IFERROR((V11-U11)/U11,"-") -> - | W12: =IFERROR((W11-V11)/V11,"-") -> - | X12: =IFERROR((X11-W11)/W11,"-") -> - | ... AA12: =IFERROR((AA11-Z11)/Z11,"-") -> -
B13: =IF('Workout Setup'!C7=0,"",'Workout Setup'!C7) -> Body Weight Bulgarian Split-Squat | C13: ='Week 1'!I7 | D13: ='Week 2'!I7 | E13: ='Week 3'!I7 | F13: ='Week 4'!I7 | G13: ='Week 5'!I7 | H13: ='Week 6'!I7 | I13: ='Week 7'!I7 | J13: ='Week 8'!I7 | K13: ='Week 9'!I7 | L13: ='Week 10'!I7 | M13: ='Week 11'!I7 | N13: ='Week 12'!I7 | P13: ='Week 1'!G7 -> 0 | Q13: ='Week 2'!G7 -> 0 | R13: ='Week 3'!G7 -> 0 | S13: ='Week 4'!G7 -> 0 | T13: ='Week 5'!G7 -> 0 | U13: ='Week 6'!G7 -> 0 | V13: ='Week 7'!G7 -> 0 | W13: ='Week 8'!G7 -> 0 | X13: ='Week 9'!G7 -> 0 | Y13: ='Week 10'!G7 -> 0 | Z13: ='Week 11'!G7 -> 0 | AA13: ='Week 12'!G7 -> 0
C14: - | D14: =IFERROR((D13-C13)/C13,"-") -> - | E14: =IFERROR((E13-D13)/D13,"-") -> - | F14: =IFERROR((F13-E13)/E13,"-") -> - | G14: =IFERROR((G13-F13)/F13,"-") -> - | H14: =IFERROR((H13-G13)/G13,"-") -> - | I14: =IFERROR((I13-H13)/H13,"-") -> - | J14: =IFERROR((J13-I13)/I13,"-") -> - | K14: =IFERROR((K13-J13)/J13,"-") -> - | ... N14: =IFERROR((N13-M13)/M13,"-") -> - | P14: - | Q14: =IFERROR((Q13-P13)/P13,"-") -> - | R14: =IFERROR((R13-Q13)/Q13,"-") -> - | S14: =IFERROR((S13-R13)/R13,"-") -> - | T14: =IFERROR((T13-S13)/S13,"-") -> - | U14: =IFERROR((U13-T13)/T13,"-") -> - | V14: =IFERROR((V13-U13)/U13,"-") -> - | W14: =IFERROR((W13-V13)/V13,"-") -> - | X14: =IFERROR((X13-W13)/W13,"-") -> - | ... AA14: =IFERROR((AA13-Z13)/Z13,"-") -> -
B15: =IF('Workout Setup'!C8=0,"",'Workout Setup'!C8) -> Dumbbell Calf Raise | C15: ='Week 1'!I8 | D15: ='Week 2'!I8 | E15: ='Week 3'!I8 | F15: ='Week 4'!I8 | G15: ='Week 5'!I8 | H15: ='Week 6'!I8 | I15: ='Week 7'!I8 | J15: ='Week 8'!I8 | K15: ='Week 9'!I8 | L15: ='Week 10'!I8 | M15: ='Week 11'!I8 | N15: ='Week 12'!I8 | P15: ='Week 1'!G8 -> 0 | Q15: ='Week 2'!G8 -> 0 | R15: ='Week 3'!G8 -> 0 | S15: ='Week 4'!G8 -> 0 | T15: ='Week 5'!G8 -> 0 | U15: ='Week 6'!G8 -> 0 | V15: ='Week 7'!G8 -> 0 | W15: ='Week 8'!G8 -> 0 | X15: ='Week 9'!G8 -> 0 | Y15: ='Week 10'!G8 -> 0 | Z15: ='Week 11'!G8 -> 0 | AA15: ='Week 12'!G8 -> 0
C16: - | D16: =IFERROR((D15-C15)/C15,"-") -> - | E16: =IFERROR((E15-D15)/D15,"-") -> - | F16: =IFERROR((F15-E15)/E15,"-") -> - | G16: =IFERROR((G15-F15)/F15,"-") -> - | H16: =IFERROR((H15-G15)/G15,"-") -> - | I16: =IFERROR((I15-H15)/H15,"-") -> - | J16: =IFERROR((J15-I15)/I15,"-") -> - | K16: =IFERROR((K15-J15)/J15,"-") -> - | ... N16: =IFERROR((N15-M15)/M15,"-") -> - | P16: - | Q16: =IFERROR((Q15-P15)/P15,"-") -> - | R16: =IFERROR((R15-Q15)/Q15,"-") -> - | S16: =IFERROR((S15-R15)/R15,"-") -> - | T16: =IFERROR((T15-S15)/S15,"-") -> - | U16: =IFERROR((U15-T15)/T15,"-") -> - | V16: =IFERROR((V15-U15)/U15,"-") -> - | W16: =IFERROR((W15-V15)/V15,"-") -> - | X16: =IFERROR((X15-W15)/W15,"-") -> - | ... AA16: =IFERROR((AA15-Z15)/Z15,"-") -> -
B17: =IF('Workout Setup'!C9=0,"",'Workout Setup'!C9) -> Machine Calf Raise | C17: ='Week 1'!I9 | D17: ='Week 2'!I9 | E17: ='Week 3'!I9 | F17: ='Week 4'!I9 | G17: ='Week 5'!I9 | H17: ='Week 6'!I9 | I17: ='Week 7'!I9 | J17: ='Week 8'!I9 | K17: ='Week 9'!I9 | L17: ='Week 10'!I9 | M17: ='Week 11'!I9 | N17: ='Week 12'!I9 | P17: ='Week 1'!G9 -> 0 | Q17: ='Week 2'!G9 -> 0 | R17: ='Week 3'!G9 -> 0 | S17: ='Week 4'!G9 -> 0 | T17: ='Week 5'!G9 -> 0 | U17: ='Week 6'!G9 -> 0 | V17: ='Week 7'!G9 -> 0 | W17: ='Week 8'!G9 -> 0 | X17: ='Week 9'!G9 -> 0 | Y17: ='Week 10'!G9 -> 0 | Z17: ='Week 11'!G9 -> 0 | AA17: ='Week 12'!G9 -> 0
C18: - | D18: =IFERROR((D17-C17)/C17,"-") -> - | E18: =IFERROR((E17-D17)/D17,"-") -> - | F18: =IFERROR((F17-E17)/E17,"-") -> - | G18: =IFERROR((G17-F17)/F17,"-") -> - | H18: =IFERROR((H17-G17)/G17,"-") -> - | I18: =IFERROR((I17-H17)/H17,"-") -> - | J18: =IFERROR((J17-I17)/I17,"-") -> - | K18: =IFERROR((K17-J17)/J17,"-") -> - | ... N18: =IFERROR((N17-M17)/M17,"-") -> - | P18: - | Q18: =IFERROR((Q17-P17)/P17,"-") -> - | R18: =IFERROR((R17-Q17)/Q17,"-") -> - | S18: =IFERROR((S17-R17)/R17,"-") -> - | T18: =IFERROR((T17-S17)/S17,"-") -> - | U18: =IFERROR((U17-T17)/T17,"-") -> - | V18: =IFERROR((V17-U17)/U17,"-") -> - | W18: =IFERROR((W17-V17)/V17,"-") -> - | X18: =IFERROR((X17-W17)/W17,"-") -> - | ... AA18: =IFERROR((AA17-Z17)/Z17,"-") -> -
A21: Day 2 | B21: =IF('Workout Setup'!C13=0,"",'Workout Setup'!C13) -> Cable Narrow-Grip Lat Pull-Down | C21: ='Week 1'!I13 | D21: ='Week 2'!I13 | E21: ='Week 3'!I13 | F21: ='Week 4'!I13 | G21: ='Week 5'!I13 | H21: ='Week 6'!I13 | I21: ='Week 7'!I13 | J21: ='Week 8'!I13 | K21: ='Week 9'!I13 | L21: ='Week 10'!I13 | M21: ='Week 11'!I13 | N21: ='Week 12'!I13 | P21: ='Week 1'!G13 -> 0 | Q21: ='Week 2'!G13 -> 0 | R21: ='Week 3'!G13 -> 0 | S21: ='Week 4'!G13 -> 0 | T21: ='Week 5'!G13 -> 0 | U21: ='Week 6'!G13 -> 0 | V21: ='Week 7'!G13 -> 0 | W21: ='Week 8'!G13 -> 0 | X21: ='Week 9'!G13 -> 0 | Y21: ='Week 10'!G13 -> 0 | Z21: ='Week 11'!G13 -> 0 | AA21: ='Week 12'!G13 -> 0
C22: - | D22: =IFERROR((D21-C21)/C21,"-") -> - | E22: =IFERROR((E21-D21)/D21,"-") -> - | F22: =IFERROR((F21-E21)/E21,"-") -> - | G22: =IFERROR((G21-F21)/F21,"-") -> - | H22: =IFERROR((H21-G21)/G21,"-") -> - | I22: =IFERROR((I21-H21)/H21,"-") -> - | J22: =IFERROR((J21-I21)/I21,"-") -> - | K22: =IFERROR((K21-J21)/J21,"-") -> - | ... N22: =IFERROR((N21-M21)/M21,"-") -> - | P22: - | Q22: =IFERROR((Q21-P21)/P21,"-") -> - | R22: =IFERROR((R21-Q21)/Q21,"-") -> - | S22: =IFERROR((S21-R21)/R21,"-") -> - | T22: =IFERROR((T21-S21)/S21,"-") -> - | U22: =IFERROR((U21-T21)/T21,"-") -> - | V22: =IFERROR((V21-U21)/U21,"-") -> - | W22: =IFERROR((W21-V21)/V21,"-") -> - | X22: =IFERROR((X21-W21)/W21,"-") -> - | ... AA22: =IFERROR((AA21-Z21)/Z21,"-") -> -
B23: =IF('Workout Setup'!C14=0,"",'Workout Setup'!C14) -> Cable Wide-Grip Lat Pull-Down | C23: ='Week 1'!I14 | D23: ='Week 2'!I14 | E23: ='Week 3'!I14 | F23: ='Week 4'!I14 | G23: ='Week 5'!I14 | H23: ='Week 6'!I14 | I23: ='Week 7'!I14 | J23: ='Week 8'!I14 | K23: ='Week 9'!I14 | L23: ='Week 10'!I14 | M23: ='Week 11'!I14 | N23: ='Week 12'!I14 | P23: ='Week 1'!G14 -> 0 | Q23: ='Week 2'!G14 -> 0 | R23: ='Week 3'!G14 -> 0 | S23: ='Week 4'!G14 -> 0 | T23: ='Week 5'!G14 -> 0 | U23: ='Week 6'!G14 -> 0 | V23: ='Week 7'!G14 -> 0 | W23: ='Week 8'!G14 -> 0 | X23: ='Week 9'!G14 -> 0 | Y23: ='Week 10'!G14 -> 0 | Z23: ='Week 11'!G14 -> 0 | AA23: ='Week 12'!G14 -> 0
C24: - | D24: =IFERROR((D23-C23)/C23,"-") -> - | E24: =IFERROR((E23-D23)/D23,"-") -> - | F24: =IFERROR((F23-E23)/E23,"-") -> - | G24: =IFERROR((G23-F23)/F23,"-") -> - | H24: =IFERROR((H23-G23)/G23,"-") -> - | I24: =IFERROR((I23-H23)/H23,"-") -> - | J24: =IFERROR((J23-I23)/I23,"-") -> - | K24: =IFERROR((K23-J23)/J23,"-") -> - | ... N24: =IFERROR((N23-M23)/M23,"-") -> - | P24: - | Q24: =IFERROR((Q23-P23)/P23,"-") -> - | R24: =IFERROR((R23-Q23)/Q23,"-") -> - | S24: =IFERROR((S23-R23)/R23,"-") -> - | T24: =IFERROR((T23-S23)/S23,"-") -> - | U24: =IFERROR((U23-T23)/T23,"-") -> - | V24: =IFERROR((V23-U23)/U23,"-") -> - | W24: =IFERROR((W23-V23)/V23,"-") -> - | X24: =IFERROR((X23-W23)/W23,"-") -> - | ... AA24: =IFERROR((AA23-Z23)/Z23,"-") -> -
B25: =IF('Workout Setup'!C15=0,"",'Workout Setup'!C15) -> Machine Back Extension | C25: ='Week 1'!I15 | D25: ='Week 2'!I15 | E25: ='Week 3'!I15 | F25: ='Week 4'!I15 | G25: ='Week 5'!I15 | H25: ='Week 6'!I15 | I25: ='Week 7'!I15 | J25: ='Week 8'!I15 | K25: ='Week 9'!I15 | L25: ='Week 10'!I15 | M25: ='Week 11'!I15 | N25: ='Week 12'!I15 | P25: ='Week 1'!G15 -> 0 | Q25: ='Week 2'!G15 -> 0 | R25: ='Week 3'!G15 -> 0 | S25: ='Week 4'!G15 -> 0 | T25: ='Week 5'!G15 -> 0 | U25: ='Week 6'!G15 -> 0 | V25: ='Week 7'!G15 -> 0 | W25: ='Week 8'!G15 -> 0 | X25: ='Week 9'!G15 -> 0 | Y25: ='Week 10'!G15 -> 0 | Z25: ='Week 11'!G15 -> 0 | AA25: ='Week 12'!G15 -> 0
C26: - | D26: =IFERROR((D25-C25)/C25,"-") -> - | E26: =IFERROR((E25-D25)/D25,"-") -> - | F26: =IFERROR((F25-E25)/E25,"-") -> - | G26: =IFERROR((G25-F25)/F25,"-") -> - | H26: =IFERROR((H25-G25)/G25,"-") -> - | I26: =IFERROR((I25-H25)/H25,"-") -> - | J26: =IFERROR((J25-I25)/I25,"-") -> - | K26: =IFERROR((K25-J25)/J25,"-") -> - | ... N26: =IFERROR((N25-M25)/M25,"-") -> - | P26: - | Q26: =IFERROR((Q25-P25)/P25,"-") -> - | R26: =IFERROR((R25-Q25)/Q25,"-") -> - | S26: =IFERROR((S25-R25)/R25,"-") -> - | T26: =IFERROR((T25-S25)/S25,"-") -> - | U26: =IFERROR((U25-T25)/T25,"-") -> - | V26: =IFERROR((V25-U25)/U25,"-") -> - | W26: =IFERROR((W25-V25)/V25,"-") -> - | X26: =IFERROR((X25-W25)/W25,"-") -> - | ... AA26: =IFERROR((AA25-Z25)/Z25,"-") -> -
B27: =IF('Workout Setup'!C16=0,"",'Workout Setup'!C16) -> Body Weight Bench Dip | C27: ='Week 1'!I16 | D27: ='Week 2'!I16 | E27: ='Week 3'!I16 | F27: ='Week 4'!I16 | G27: ='Week 5'!I16 | H27: ='Week 6'!I16 | I27: ='Week 7'!I16 | J27: ='Week 8'!I16 | K27: ='Week 9'!I16 | L27: ='Week 10'!I16 | M27: ='Week 11'!I16 | N27: ='Week 12'!I16 | P27: ='Week 1'!G16 -> 0 | Q27: ='Week 2'!G16 -> 0 | R27: ='Week 3'!G16 -> 0 | S27: ='Week 4'!G16 -> 0 | T27: ='Week 5'!G16 -> 0 | U27: ='Week 6'!G16 -> 0 | V27: ='Week 7'!G16 -> 0 | W27: ='Week 8'!G16 -> 0 | X27: ='Week 9'!G16 -> 0 | Y27: ='Week 10'!G16 -> 0 | Z27: ='Week 11'!G16 -> 0 | AA27: ='Week 12'!G16 -> 0
C28: - | D28: =IFERROR((D27-C27)/C27,"-") -> - | E28: =IFERROR((E27-D27)/D27,"-") -> - | F28: =IFERROR((F27-E27)/E27,"-") -> - | G28: =IFERROR((G27-F27)/F27,"-") -> - | H28: =IFERROR((H27-G27)/G27,"-") -> - | I28: =IFERROR((I27-H27)/H27,"-") -> - | J28: =IFERROR((J27-I27)/I27,"-") -> - | K28: =IFERROR((K27-J27)/J27,"-") -> - | ... N28: =IFERROR((N27-M27)/M27,"-") -> - | P28: - | Q28: =IFERROR((Q27-P27)/P27,"-") -> - | R28: =IFERROR((R27-Q27)/Q27,"-") -> - | S28: =IFERROR((S27-R27)/R27,"-") -> - | T28: =IFERROR((T27-S27)/S27,"-") -> - | U28: =IFERROR((U27-T27)/T27,"-") -> - | V28: =IFERROR((V27-U27)/U27,"-") -> - | W28: =IFERROR((W27-V27)/V27,"-") -> - | X28: =IFERROR((X27-W27)/W27,"-") -> - | ... AA28: =IFERROR((AA27-Z27)/Z27,"-") -> -
B29: =IF('Workout Setup'!C17=0,"",'Workout Setup'!C17) -> Cable Overhead Triceps Extension | C29: ='Week 1'!I17 | D29: ='Week 2'!I17 | E29: ='Week 3'!I17 | F29: ='Week 4'!I17 | G29: ='Week 5'!I17 | H29: ='Week 6'!I17 | I29: ='Week 7'!I17 | J29: ='Week 8'!I17 | K29: ='Week 9'!I17 | L29: ='Week 10'!I17 | M29: ='Week 11'!I17 | N29: ='Week 12'!I17 | P29: ='Week 1'!G17 -> 0 | Q29: ='Week 2'!G17 -> 0 | R29: ='Week 3'!G17 -> 0 | S29: ='Week 4'!G17 -> 0 | T29: ='Week 5'!G17 -> 0 | U29: ='Week 6'!G17 -> 0 | V29: ='Week 7'!G17 -> 0 | W29: ='Week 8'!G17 -> 0 | X29: ='Week 9'!G17 -> 0 | Y29: ='Week 10'!G17 -> 0 | Z29: ='Week 11'!G17 -> 0 | AA29: ='Week 12'!G17 -> 0
C30: - | D30: =IFERROR((D29-C29)/C29,"-") -> - | E30: =IFERROR((E29-D29)/D29,"-") -> - | F30: =IFERROR((F29-E29)/E29,"-") -> - | G30: =IFERROR((G29-F29)/F29,"-") -> - | H30: =IFERROR((H29-G29)/G29,"-") -> - | I30: =IFERROR((I29-H29)/H29,"-") -> - | J30: =IFERROR((J29-I29)/I29,"-") -> - | K30: =IFERROR((K29-J29)/J29,"-") -> - | ... N30: =IFERROR((N29-M29)/M29,"-") -> - | P30: - | Q30: =IFERROR((Q29-P29)/P29,"-") -> - | R30: =IFERROR((R29-Q29)/Q29,"-") -> - | S30: =IFERROR((S29-R29)/R29,"-") -> - | T30: =IFERROR((T29-S29)/S29,"-") -> - | U30: =IFERROR((U29-T29)/T29,"-") -> - | V30: =IFERROR((V29-U29)/U29,"-") -> - | W30: =IFERROR((W29-V29)/V29,"-") -> - | X30: =IFERROR((X29-W29)/W29,"-") -> - | ... AA30: =IFERROR((AA29-Z29)/Z29,"-") -> -
B31: =IF('Workout Setup'!C18=0,"",'Workout Setup'!C18) -> Machine Triceps Extension | C31: ='Week 1'!I18 | D31: ='Week 2'!I18 | E31: ='Week 3'!I18 | F31: ='Week 4'!I18 | G31: ='Week 5'!I18 | H31: ='Week 6'!I18 | I31: ='Week 7'!I18 | J31: ='Week 8'!I18 | K31: ='Week 9'!I18 | L31: ='Week 10'!I18 | M31: ='Week 11'!I18 | N31: ='Week 12'!I18 | P31: ='Week 1'!G18 -> 0 | Q31: ='Week 2'!G18 -> 0 | R31: ='Week 3'!G18 -> 0 | S31: ='Week 4'!G18 -> 0 | T31: ='Week 5'!G18 -> 0 | U31: ='Week 6'!G18 -> 0 | V31: ='Week 7'!G18 -> 0 | W31: ='Week 8'!G18 -> 0 | X31: ='Week 9'!G18 -> 0 | Y31: ='Week 10'!G18 -> 0 | Z31: ='Week 11'!G18 -> 0 | AA31: ='Week 12'!G18 -> 0
C32: - | D32: =IFERROR((D31-C31)/C31,"-") -> - | E32: =IFERROR((E31-D31)/D31,"-") -> - | F32: =IFERROR((F31-E31)/E31,"-") -> - | G32: =IFERROR((G31-F31)/F31,"-") -> - | H32: =IFERROR((H31-G31)/G31,"-") -> - | I32: =IFERROR((I31-H31)/H31,"-") -> - | J32: =IFERROR((J31-I31)/I31,"-") -> - | K32: =IFERROR((K31-J31)/J31,"-") -> - | ... N32: =IFERROR((N31-M31)/M31,"-") -> - | P32: - | Q32: =IFERROR((Q31-P31)/P31,"-") -> - | R32: =IFERROR((R31-Q31)/Q31,"-") -> - | S32: =IFERROR((S31-R31)/R31,"-") -> - | T32: =IFERROR((T31-S31)/S31,"-") -> - | U32: =IFERROR((U31-T31)/T31,"-") -> - | V32: =IFERROR((V31-U31)/U31,"-") -> - | W32: =IFERROR((W31-V31)/V31,"-") -> - | X32: =IFERROR((X31-W31)/W31,"-") -> - | ... AA32: =IFERROR((AA31-Z31)/Z31,"-") -> -
B33: =IF('Workout Setup'!C19=0,"",'Workout Setup'!C19) -> Body Weight Hanging Leg Raise | C33: ='Week 1'!I19 | D33: ='Week 2'!I19 | E33: ='Week 3'!I19 | F33: ='Week 4'!I19 | G33: ='Week 5'!I19 | H33: ='Week 6'!I19 | I33: ='Week 7'!I19 | J33: ='Week 8'!I19 | K33: ='Week 9'!I19 | L33: ='Week 10'!I19 | M33: ='Week 11'!I19 | N33: ='Week 12'!I19 | P33: ='Week 1'!G19 -> 0 | Q33: ='Week 2'!G19 -> 0 | R33: ='Week 3'!G19 -> 0 | S33: ='Week 4'!G19 -> 0 | T33: ='Week 5'!G19 -> 0 | U33: ='Week 6'!G19 -> 0 | V33: ='Week 7'!G19 -> 0 | W33: ='Week 8'!G19 -> 0 | X33: ='Week 9'!G19 -> 0 | Y33: ='Week 10'!G19 -> 0 | Z33: ='Week 11'!G19 -> 0 | AA33: ='Week 12'!G19 -> 0
C34: - | D34: =IFERROR((D33-C33)/C33,"-") -> - | E34: =IFERROR((E33-D33)/D33,"-") -> - | F34: =IFERROR((F33-E33)/E33,"-") -> - | G34: =IFERROR((G33-F33)/F33,"-") -> - | H34: =IFERROR((H33-G33)/G33,"-") -> - | I34: =IFERROR((I33-H33)/H33,"-") -> - | J34: =IFERROR((J33-I33)/I33,"-") -> - | K34: =IFERROR((K33-J33)/J33,"-") -> - | ... N34: =IFERROR((N33-M33)/M33,"-") -> - | P34: - | Q34: =IFERROR((Q33-P33)/P33,"-") -> - | R34: =IFERROR((R33-Q33)/Q33,"-") -> - | S34: =IFERROR((S33-R33)/R33,"-") -> - | T34: =IFERROR((T33-S33)/S33,"-") -> - | U34: =IFERROR((U33-T33)/T33,"-") -> - | V34: =IFERROR((V33-U33)/U33,"-") -> - | W34: =IFERROR((W33-V33)/V33,"-") -> - | X34: =IFERROR((X33-W33)/W33,"-") -> - | ... AA34: =IFERROR((AA33-Z33)/Z33,"-") -> -
B35: =IF('Workout Setup'!C20=0,"",'Workout Setup'!C20) -> Body Weight Ab Crunch | C35: ='Week 1'!I20 | D35: ='Week 2'!I20 | E35: ='Week 3'!I20 | F35: ='Week 4'!I20 | G35: ='Week 5'!I20 | H35: ='Week 6'!I20 | I35: ='Week 7'!I20 | J35: ='Week 8'!I20 | K35: ='Week 9'!I20 | L35: ='Week 10'!I20 | M35: ='Week 11'!I20 | N35: ='Week 12'!I20 | P35: ='Week 1'!G20 -> 0 | Q35: ='Week 2'!G20 -> 0 | R35: ='Week 3'!G20 -> 0 | S35: ='Week 4'!G20 -> 0 | T35: ='Week 5'!G20 -> 0 | U35: ='Week 6'!G20 -> 0 | V35: ='Week 7'!G20 -> 0 | W35: ='Week 8'!G20 -> 0 | X35: ='Week 9'!G20 -> 0 | Y35: ='Week 10'!G20 -> 0 | Z35: ='Week 11'!G20 -> 0 | AA35: ='Week 12'!G20 -> 0
C36: - | D36: =IFERROR((D35-C35)/C35,"-") -> - | E36: =IFERROR((E35-D35)/D35,"-") -> - | F36: =IFERROR((F35-E35)/E35,"-") -> - | G36: =IFERROR((G35-F35)/F35,"-") -> - | H36: =IFERROR((H35-G35)/G35,"-") -> - | I36: =IFERROR((I35-H35)/H35,"-") -> - | J36: =IFERROR((J35-I35)/I35,"-") -> - | K36: =IFERROR((K35-J35)/J35,"-") -> - | ... N36: =IFERROR((N35-M35)/M35,"-") -> - | P36: - | Q36: =IFERROR((Q35-P35)/P35,"-") -> - | R36: =IFERROR((R35-Q35)/Q35,"-") -> - | S36: =IFERROR((S35-R35)/R35,"-") -> - | T36: =IFERROR((T35-S35)/S35,"-") -> - | U36: =IFERROR((U35-T35)/T35,"-") -> - | V36: =IFERROR((V35-U35)/U35,"-") -> - | W36: =IFERROR((W35-V35)/V35,"-") -> - | X36: =IFERROR((X35-W35)/W35,"-") -> - | ... AA36: =IFERROR((AA35-Z35)/Z35,"-") -> -
A39: Day 3 | B39: =IF('Workout Setup'!C24=0,"",'Workout Setup'!C24) -> Dumbbell Hammer Biceps Curl | C39: ='Week 1'!I24 | D39: ='Week 2'!I24 | E39: ='Week 3'!I24 | F39: ='Week 4'!I24 | G39: ='Week 5'!I24 | H39: ='Week 6'!I24 | I39: ='Week 7'!I24 | J39: ='Week 8'!I24 | K39: ='Week 9'!I24 | L39: ='Week 10'!I24 | M39: ='Week 11'!I24 | N39: ='Week 12'!I24 | P39: ='Week 1'!G24 -> 0 | Q39: ='Week 2'!G24 -> 0 | R39: ='Week 3'!G24 -> 0 | S39: ='Week 4'!G24 -> 0 | T39: ='Week 5'!G24 -> 0 | U39: ='Week 6'!G24 -> 0 | V39: ='Week 7'!G24 -> 0 | W39: ='Week 8'!G24 -> 0 | X39: ='Week 9'!G24 -> 0 | Y39: ='Week 10'!G24 -> 0 | Z39: ='Week 11'!G24 -> 0 | AA39: ='Week 12'!G24 -> 0
C40: - | D40: =IFERROR((D39-C39)/C39,"-") -> - | E40: =IFERROR((E39-D39)/D39,"-") -> - | F40: =IFERROR((F39-E39)/E39,"-") -> - | G40: =IFERROR((G39-F39)/F39,"-") -> - | H40: =IFERROR((H39-G39)/G39,"-") -> - | I40: =IFERROR((I39-H39)/H39,"-") -> - | J40: =IFERROR((J39-I39)/I39,"-") -> - | K40: =IFERROR((K39-J39)/J39,"-") -> - | ... N40: =IFERROR((N39-M39)/M39,"-") -> - | P40: - | Q40: =IFERROR((Q39-P39)/P39,"-") -> - | R40: =IFERROR((R39-Q39)/Q39,"-") -> - | S40: =IFERROR((S39-R39)/R39,"-") -> - | T40: =IFERROR((T39-S39)/S39,"-") -> - | U40: =IFERROR((U39-T39)/T39,"-") -> - | V40: =IFERROR((V39-U39)/U39,"-") -> - | W40: =IFERROR((W39-V39)/V39,"-") -> - | X40: =IFERROR((X39-W39)/W39,"-") -> - | ... AA40: =IFERROR((AA39-Z39)/Z39,"-") -> -
B41: =IF('Workout Setup'!C25=0,"",'Workout Setup'!C25) -> Dumbbell Incline Bench Biceps Curl | C41: ='Week 1'!I25 | D41: ='Week 2'!I25 | E41: ='Week 3'!I25 | F41: ='Week 4'!I25 | G41: ='Week 5'!I25 | H41: ='Week 6'!I25 | I41: ='Week 7'!I25 | J41: ='Week 8'!I25 | K41: ='Week 9'!I25 | L41: ='Week 10'!I25 | M41: ='Week 11'!I25 | N41: ='Week 12'!I25 | P41: ='Week 1'!G25 -> 0 | Q41: ='Week 2'!G25 -> 0 | R41: ='Week 3'!G25 -> 0 | S41: ='Week 4'!G25 -> 0 | T41: ='Week 5'!G25 -> 0 | U41: ='Week 6'!G25 -> 0 | V41: ='Week 7'!G25 -> 0 | W41: ='Week 8'!G25 -> 0 | X41: ='Week 9'!G25 -> 0 | Y41: ='Week 10'!G25 -> 0 | Z41: ='Week 11'!G25 -> 0 | AA41: ='Week 12'!G25 -> 0
C42: - | D42: =IFERROR((D41-C41)/C41,"-") -> - | E42: =IFERROR((E41-D41)/D41,"-") -> - | F42: =IFERROR((F41-E41)/E41,"-") -> - | G42: =IFERROR((G41-F41)/F41,"-") -> - | H42: =IFERROR((H41-G41)/G41,"-") -> - | I42: =IFERROR((I41-H41)/H41,"-") -> - | J42: =IFERROR((J41-I41)/I41,"-") -> - | K42: =IFERROR((K41-J41)/J41,"-") -> - | ... N42: =IFERROR((N41-M41)/M41,"-") -> - | P42: - | Q42: =IFERROR((Q41-P41)/P41,"-") -> - | R42: =IFERROR((R41-Q41)/Q41,"-") -> - | S42: =IFERROR((S41-R41)/R41,"-") -> - | T42: =IFERROR((T41-S41)/S41,"-") -> - | U42: =IFERROR((U41-T41)/T41,"-") -> - | V42: =IFERROR((V41-U41)/U41,"-") -> - | W42: =IFERROR((W41-V41)/V41,"-") -> - | X42: =IFERROR((X41-W41)/W41,"-") -> - | ... AA42: =IFERROR((AA41-Z41)/Z41,"-") -> -
B43: =IF('Workout Setup'!C26=0,"",'Workout Setup'!C26) -> Barbell Preacher Biceps Curl | C43: ='Week 1'!I26 | D43: ='Week 2'!I26 | E43: ='Week 3'!I26 | F43: ='Week 4'!I26 | G43: ='Week 5'!I26 | H43: ='Week 6'!I26 | I43: ='Week 7'!I26 | J43: ='Week 8'!I26 | K43: ='Week 9'!I26 | L43: ='Week 10'!I26 | M43: ='Week 11'!I26 | N43: ='Week 12'!I26 | P43: ='Week 1'!G26 -> 0 | Q43: ='Week 2'!G26 -> 0 | R43: ='Week 3'!G26 -> 0 | S43: ='Week 4'!G26 -> 0 | T43: ='Week 5'!G26 -> 0 | U43: ='Week 6'!G26 -> 0 | V43: ='Week 7'!G26 -> 0 | W43: ='Week 8'!G26 -> 0 | X43: ='Week 9'!G26 -> 0 | Y43: ='Week 10'!G26 -> 0 | Z43: ='Week 11'!G26 -> 0 | AA43: ='Week 12'!G26 -> 0
C44: - | D44: =IFERROR((D43-C43)/C43,"-") -> - | E44: =IFERROR((E43-D43)/D43,"-") -> - | F44: =IFERROR((F43-E43)/E43,"-") -> - | G44: =IFERROR((G43-F43)/F43,"-") -> - | H44: =IFERROR((H43-G43)/G43,"-") -> - | I44: =IFERROR((I43-H43)/H43,"-") -> - | J44: =IFERROR((J43-I43)/I43,"-") -> - | K44: =IFERROR((K43-J43)/J43,"-") -> - | ... N44: =IFERROR((N43-M43)/M43,"-") -> - | P44: - | Q44: =IFERROR((Q43-P43)/P43,"-") -> - | R44: =IFERROR((R43-Q43)/Q43,"-") -> - | S44: =IFERROR((S43-R43)/R43,"-") -> - | T44: =IFERROR((T43-S43)/S43,"-") -> - | U44: =IFERROR((U43-T43)/T43,"-") -> - | V44: =IFERROR((V43-U43)/U43,"-") -> - | W44: =IFERROR((W43-V43)/V43,"-") -> - | X44: =IFERROR((X43-W43)/W43,"-") -> - | ... AA44: =IFERROR((AA43-Z43)/Z43,"-") -> -
...

Sheet Workout Setup
A1: Day 1 | B1: Muscle Group | C1: Exercise | D1: Sets | E1: Reps | F1: Rest (Seconds) | G1: Weight | H1: Note
B2: Glutes_Hamstrings | C2: Barbell Glute Bridge | D2: 3 | E2: 8 - 12 | F2: 30
B3: Glutes_Hamstrings | C3: Barbell Hip Thrust | D3: 3 | E3: 8 - 12 | F3: 30
B4: Glutes_Hamstrings | C4: Cable One-Legged Kickback | D4: 3 | E4: 8 - 12 | F4: 30
B5: Quadriceps | C5: Barbell Squat | D5: 3 | E5: 8 - 12 | F5: 30
B6: Quadriceps | C6: Machine Laying Leg Press | D6: 3 | E6: 8 - 12 | F6: 30
B7: Quadriceps | C7: Body Weight Bulgarian Split-Squat | D7: 3 | E7: 8 - 12 | F7: 30
B8: Calves | C8: Dumbbell Calf Raise | D8: 3 | E8: 15 - 20 | F8: 30
B9: Quadriceps | C9: Machine Calf Raise | D9: 3 | E9: 15 - 20 | F9: 30
A12: Day 2 | B12: Muscle Group | C12: Exercise | D12: Sets | E12: Reps | F12: Rest (Seconds) | G12: Weight | H12: Note
B13: Back | C13: Cable Narrow-Grip Lat Pull-Down | D13: 3 | E13: 8 - 12 | F13: 30
B14: Back | C14: Cable Wide-Grip Lat Pull-Down | D14: 3 | E14: 8 - 12 | F14: 30
B15: Back | C15: Machine Back Extension | D15: 3 | E15: 8 - 12 | F15: 30
B16: Triceps | C16: Body Weight Bench Dip | D16: 3 | E16: 8 - 12 | F16: 30
B17: Triceps | C17: Cable Overhead Triceps Extension | D17: 3 | E17: 8 - 12 | F17: 30
B18: Triceps | C18: Machine Triceps Extension | D18: 3 | E18: 8 - 12 | F18: 30
B19: Abs | C19: Body Weight Hanging Leg Raise | D19: 3 | E19: 15 - 20 | F19: 30
B20: Abs | C20: Body Weight Ab Crunch | D20: 3 | E20: 15 - 20 | F20: 30
A23: Day 3 | B23: Muscle Group | C23: Exercise | D23: Sets | E23: Reps | F23: Rest (Seconds) | G23: Weight | H23: Note
B24: Biceps | C24: Dumbbell Hammer Biceps Curl | D24: 3 | E24: 8 - 12 | F24: 30
B25: Biceps | C25: Dumbbell Incline Bench Biceps Curl | D25: 3 | E25: 8 - 12 | F25: 30
B26: Biceps | C26: Barbell Preacher Biceps Curl | D26: 3 | E26: 8 - 12 | F26: 30
B27: Shoulders | C27: Dumbbell Side Lateral Raise | D27: 3 | E27: 8 - 12 | F27: 30
B28: Shoulders | C28: Dumbbell Seated Shoulder Press | D28: 3 | E28: 8 - 12 | F28: 30
B29: Shoulders | C29: Dumbbell Front Raise | D29: 3 | E29: 8 - 12 | F29: 30
B30: Chest | C30: Machine Chest Press | D30: 3 | E30: 8 - 12 | F30: 30
B31: Chest | C31: Weighted Dip (Chest Variation) | D31: 3 | E31: 8 - 12 | F31: 30
A34: Day 4 | B34: Muscle Group | C34: Exercise | D34: Sets | E34: Reps | F34: Rest (Seconds) | G34: Weight | H34: Note
B35: Glutes_Hamstrings | C35: Banded Leg Extension | D35: 3 | E35: 20 - 25 | F35: 30
B36: Quadriceps | C36: Dumbbell Goblet Squat | D36: 3 | E36: 8 - 10 | F36: 30
B37: Quadriceps | C37: Hip Ab/Adduction (Pulse) | D37: 3 | E37: 6 - 8 | F37: 30
B38: Other | C38: ITB release via Foam roller | D38: 3 | E38: 8 - 12 | F38: 30
B39: Other | C39: TFL release via Trigger ball | D39: 3 | E39: 8 - 12 | F39: 30
B40: Calves | C40: Single Leg Seated Calf Raise | D40: 3 | E40: 12 - 15 | F40: 30
B41: Calves | C41: Machine Calf Raise | D41: 3 | E41: 12 - 15 | F41: 30
B42: Glutes_Hamstrings | C42: Double Leg Hamstring Bridge | D42: 3 | E42: 15 - 20 | F42: 30

Sheet Week 1
A1: Day 1 | B1: Muscle Group | C1: Exercise | D1: Sets | E1: Reps | F1: Rest (Seconds) | G1: Weight | H1: Total Reps | I1: Volume | J1: Note
B2: =IF('Workout Setup'!B2=0,"",'Workout Setup'!B2) -> Glutes_Hamstrings | C2: =IF('Workout Setup'!C2=0,"",'Workout Setup'!C2) -> Barbell Glute Bridge | D2: =IF('Workout Setup'!D2=0,"",'Workout Setup'!D2) -> 3 | E2: =IF('Workout Setup'!E2=0,"",'Workout Setup'!E2) -> 8 - 12 | F2: =IF('Workout Setup'!F2=0,"",'Workout Setup'!F2) -> 30 | G2: ='Workout Setup'!G2 -> 0 | I2: =IF(H2*G2=0,"",H2*G2) | J2: =IF('Workout Setup'!H2=0,"",'Workout Setup'!H2)
B3: =IF('Workout Setup'!B3=0,"",'Workout Setup'!B3) -> Glutes_Hamstrings | C3: =IF('Workout Setup'!C3=0,"",'Workout Setup'!C3) -> Barbell Hip Thrust | D3: =IF('Workout Setup'!D3=0,"",'Workout Setup'!D3) -> 3 | E3: =IF('Workout Setup'!E3=0,"",'Workout Setup'!E3) -> 8 - 12 | F3: =IF('Workout Setup'!F3=0,"",'Workout Setup'!F3) -> 30 | G3: ='Workout Setup'!G3 -> 0 | I3: =IF(H3*G3=0,"",H3*G3) | J3: =IF('Workout Setup'!H3=0,"",'Workout Setup'!H3)
B4: =IF('Workout Setup'!B4=0,"",'Workout Setup'!B4) -> Glutes_Hamstrings | C4: =IF('Workout Setup'!C4=0,"",'Workout Setup'!C4) -> Cable One-Legged Kickback | D4: =IF('Workout Setup'!D4=0,"",'Workout Setup'!D4) -> 3 | E4: =IF('Workout Setup'!E4=0,"",'Workout Setup'!E4) -> 8 - 12 | F4: =IF('Workout Setup'!F4=0,"",'Workout Setup'!F4) -> 30 | G4: ='Workout Setup'!G4 -> 0 | I4: =IF(H4*G4=0,"",H4*G4) | J4: =IF('Workout Setup'!H4=0,"",'Workout Setup'!H4)
B5: =IF('Workout Setup'!B5=0,"",'Workout Setup'!B5) -> Quadriceps | C5: =IF('Workout Setup'!C5=0,"",'Workout Setup'!C5) -> Barbell Squat | D5: =IF('Workout Setup'!D5=0,"",'Workout Setup'!D5) -> 3 | E5: =IF('Workout Setup'!E5=0,"",'Workout Setup'!E5) -> 8 - 12 | F5: =IF('Workout Setup'!F5=0,"",'Workout Setup'!F5) -> 30 | G5: ='Workout Setup'!G5 -> 0 | I5: =IF(H5*G5=0,"",H5*G5) | J5: =IF('Workout Setup'!H5=0,"",'Workout Setup'!H5)
B6: =IF('Workout Setup'!B6=0,"",'Workout Setup'!B6) -> Quadriceps | C6: =IF('Workout Setup'!C6=0,"",'Workout Setup'!C6) -> Machine Laying Leg Press | D6: =IF('Workout Setup'!D6=0,"",'Workout Setup'!D6) -> 3 | E6: =IF('Workout Setup'!E6=0,"",'Workout Setup'!E6) -> 8 - 12 | F6: =IF('Workout Setup'!F6=0,"",'Workout Setup'!F6) -> 30 | G6: ='Workout Setup'!G6 -> 0 | I6: =IF(H6*G6=0,"",H6*G6) | J6: =IF('Workout Setup'!H6=0,"",'Workout Setup'!H6)
B7: =IF('Workout Setup'!B7=0,"",'Workout Setup'!B7) -> Quadriceps | C7: =IF('Workout Setup'!C7=0,"",'Workout Setup'!C7) -> Body Weight Bulgarian Split-Squat | D7: =IF('Workout Setup'!D7=0,"",'Workout Setup'!D7) -> 3 | E7: =IF('Workout Setup'!E7=0,"",'Workout Setup'!E7) -> 8 - 12 | F7: =IF('Workout Setup'!F7=0,"",'Workout Setup'!F7) -> 30 | G7: ='Workout Setup'!G7 -> 0 | I7: =IF(H7*G7=0,"",H7*G7) | J7: =IF('Workout Setup'!H7=0,"",'Workout Setup'!H7)
B8: =IF('Workout Setup'!B8=0,"",'Workout Setup'!B8) -> Calves | C8: =IF('Workout Setup'!C8=0,"",'Workout Setup'!C8) -> Dumbbell Calf Raise | D8: =IF('Workout Setup'!D8=0,"",'Workout Setup'!D8) -> 3 | E8: =IF('Workout Setup'!E8=0,"",'Workout Setup'!E8) -> 15 - 20 | F8: =IF('Workout Setup'!F8=0,"",'Workout Setup'!F8) -> 30 | G8: ='Workout Setup'!G8 -> 0 | I8: =IF(H8*G8=0,"",H8*G8) | J8: =IF('Workout Setup'!H8=0,"",'Workout Setup'!H8)
B9: =IF('Workout Setup'!B9=0,"",'Workout Setup'!B9) -> Quadriceps | C9: =IF('Workout Setup'!C9=0,"",'Workout Setup'!C9) -> Machine Calf Raise | D9: =IF('Workout Setup'!D9=0,"",'Workout Setup'!D9) -> 3 | E9: =IF('Workout Setup'!E9=0,"",'Workout Setup'!E9) -> 15 - 20 | F9: =IF('Workout Setup'!F9=0,"",'Workout Setup'!F9) -> 30 | G9: ='Workout Setup'!G9 -> 0 | I9: =IF(H9*G9=0,"",H9*G9) | J9: =IF('Workout Setup'!H9=0,"",'Workout Setup'!H9)
A12: Day 2 | B12: Muscle Group | C12: Exercise | D12: Sets | E12: Reps | F12: Rest (Seconds) | G12: Weight | H12: Total Reps | I12: Volume | J12: Note
B13: =IF('Workout Setup'!B13=0,"",'Workout Setup'!B13) -> Back | C13: =IF('Workout Setup'!C13=0,"",'Workout Setup'!C13) -> Cable Narrow-Grip Lat Pull-Down | D13: =IF('Workout Setup'!D13=0,"",'Workout Setup'!D13) -> 3 | E13: =IF('Workout Setup'!E13=0,"",'Workout Setup'!E13) -> 8 - 12 | F13: =IF('Workout Setup'!F13=0,"",'Workout Setup'!F13) -> 30 | G13: ='Workout Setup'!G13 -> 0 | I13: =IF(H13*G13=0,"",H13*G13) | J13: =IF('Workout Setup'!H13=0,"",'Workout Setup'!H13)
B14: =IF('Workout Setup'!B14=0,"",'Workout Setup'!B14) -> Back | C14: =IF('Workout Setup'!C14=0,"",'Workout Setup'!C14) -> Cable Wide-Grip Lat Pull-Down | D14: =IF('Workout Setup'!D14=0,"",'Workout Setup'!D14) -> 3 | E14: =IF('Workout Setup'!E14=0,"",'Workout Setup'!E14) -> 8 - 12 | F14: =IF('Workout Setup'!F14=0,"",'Workout Setup'!F14) -> 30 | G14: ='Workout Setup'!G14 -> 0 | I14: =IF(H14*G14=0,"",H14*G14) | J14: =IF('Workout Setup'!H14=0,"",'Workout Setup'!H14)
B15: =IF('Workout Setup'!B15=0,"",'Workout Setup'!B15) -> Back | C15: =IF('Workout Setup'!C15=0,"",'Workout Setup'!C15) -> Machine Back Extension | D15: =IF('Workout Setup'!D15=0,"",'Workout Setup'!D15) -> 3 | E15: =IF('Workout Setup'!E15=0,"",'Workout Setup'!E15) -> 8 - 12 | F15: =IF('Workout Setup'!F15=0,"",'Workout Setup'!F15) -> 30 | G15: ='Workout Setup'!G15 -> 0 | I15: =IF(H15*G15=0,"",H15*G15) | J15: =IF('Workout Setup'!H15=0,"",'Workout Setup'!H15)
B16: =IF('Workout Setup'!B16=0,"",'Workout Setup'!B16) -> Triceps | C16: =IF('Workout Setup'!C16=0,"",'Workout Setup'!C16) -> Body Weight Bench Dip | D16: =IF('Workout Setup'!D16=0,"",'Workout Setup'!D16) -> 3 | E16: =IF('Workout Setup'!E16=0,"",'Workout Setup'!E16) -> 8 - 12 | F16: =IF('Workout Setup'!F16=0,"",'Workout Setup'!F16) -> 30 | G16: ='Workout Setup'!G16 -> 0 | I16: =IF(H16*G16=0,"",H16*G16) | J16: =IF('Workout Setup'!H16=0,"",'Workout Setup'!H16)
B17: =IF('Workout Setup'!B17=0,"",'Workout Setup'!B17) -> Triceps | C17: =IF('Workout Setup'!C17=0,"",'Workout Setup'!C17) -> Cable Overhead Triceps Extension | D17: =IF('Workout Setup'!D17=0,"",'Workout Setup'!D17) -> 3 | E17: =IF('Workout Setup'!E17=0,"",'Workout Setup'!E17) -> 8 - 12 | F17: =IF('Workout Setup'!F17=0,"",'Workout Setup'!F17) -> 30 | G17: ='Workout Setup'!G17 -> 0 | I17: =IF(H17*G17=0,"",H17*G17) | J17: =IF('Workout Setup'!H17=0,"",'Workout Setup'!H17)
B18: =IF('Workout Setup'!B18=0,"",'Workout Setup'!B18) -> Triceps | C18: =IF('Workout Setup'!C18=0,"",'Workout Setup'!C18) -> Machine Triceps Extension | D18: =IF('Workout Setup'!D18=0,"",'Workout Setup'!D18) -> 3 | E18: =IF('Workout Setup'!E18=0,"",'Workout Setup'!E18) -> 8 - 12 | F18: =IF('Workout Setup'!F18=0,"",'Workout Setup'!F18) -> 30 | G18: ='Workout Setup'!G18 -> 0 | I18: =IF(H18*G18=0,"",H18*G18) | J18: =IF('Workout Setup'!H18=0,"",'Workout Setup'!H18)
B19: =IF('Workout Setup'!B19=0,"",'Workout Setup'!B19) -> Abs | C19: =IF('Workout Setup'!C19=0,"",'Workout Setup'!C19) -> Body Weight Hanging Leg Raise | D19: =IF('Workout Setup'!D19=0,"",'Workout Setup'!D19) -> 3 | E19: =IF('Workout Setup'!E19=0,"",'Workout Setup'!E19) -> 15 - 20 | F19: =IF('Workout Setup'!F19=0,"",'Workout Setup'!F19) -> 30 | G19: ='Workout Setup'!G19 -> 0 | I19: =IF(H19*G19=0,"",H19*G19) | J19: =IF('Workout Setup'!H19=0,"",'Workout Setup'!H19)
B20: =IF('Workout Setup'!B20=0,"",'Workout Setup'!B20) -> Abs | C20: =IF('Workout Setup'!C20=0,"",'Workout Setup'!C20) -> Body Weight Ab Crunch | D20: =IF('Workout Setup'!D20=0,"",'Workout Setup'!D20) -> 3 | E20: =IF('Workout Setup'!E20=0,"",'Workout Setup'!E20) -> 15 - 20 | F20: =IF('Workout Setup'!F20=0,"",'Workout Setup'!F20) -> 30 | G20: ='Workout Setup'!G20 -> 0 | I20: =IF(H20*G20=0,"",H20*G20) | J20: =IF('Workout Setup'!H20=0,"",'Workout Setup'!H20)
A23: Day 3 | B23: Muscle Group | C23: Exercise | D23: Sets | E23: Reps | F23: Rest (Seconds) | G23: Weight | H23: Total Reps | I23: Volume | J23: Note
B24: =IF('Workout Setup'!B24=0,"",'Workout Setup'!B24) -> Biceps | C24: =IF('Workout Setup'!C24=0,"",'Workout Setup'!C24) -> Dumbbell Hammer Biceps Curl | D24: =IF('Workout Setup'!D24=0,"",'Workout Setup'!D24) -> 3 | E24: =IF('Workout Setup'!E24=0,"",'Workout Setup'!E24) -> 8 - 12 | F24: =IF('Workout Setup'!F24=0,"",'Workout Setup'!F24) -> 30 | G24: ='Workout Setup'!G24 -> 0 | I24: =IF(H24*G24=0,"",H24*G24) | J24: =IF('Workout Setup'!H24=0,"",'Workout Setup'!H24)
B25: =IF('Workout Setup'!B25=0,"",'Workout Setup'!B25) -> Biceps | C25: =IF('Workout Setup'!C25=0,"",'Workout Setup'!C25) -> Dumbbell Incline Bench Biceps Curl | D25: =IF('Workout Setup'!D25=0,"",'Workout Setup'!D25) -> 3 | E25: =IF('Workout Setup'!E25=0,"",'Workout Setup'!E25) -> 8 - 12 | F25: =IF('Workout Setup'!F25=0,"",'Workout Setup'!F25) -> 30 | G25: ='Workout Setup'!G25 -> 0 | I25: =IF(H25*G25=0,"",H25*G25) | J25: =IF('Workout Setup'!H25=0,"",'Workout Setup'!H25)
B26: =IF('Workout Setup'!B26=0,"",'Workout Setup'!B26) -> Biceps | C26: =IF('Workout Setup'!C26=0,"",'Workout Setup'!C26) -> Barbell Preacher Biceps Curl | D26: =IF('Workout Setup'!D26=0,"",'Workout Setup'!D26) -> 3 | E26: =IF('Workout Setup'!E26=0,"",'Workout Setup'!E26) -> 8 - 12 | F26: =IF('Workout Setup'!F26=0,"",'Workout Setup'!F26) -> 30 | G26: ='Workout Setup'!G26 -> 0 | I26: =IF(H26*G26=0,"",H26*G26) | J26: =IF('Workout Setup'!H26=0,"",'Workout Setup'!H26)
B27: =IF('Workout Setup'!B27=0,"",'Workout Setup'!B27) -> Shoulders | C27: =IF('Workout Setup'!C27=0,"",'Workout Setup'!C27) -> Dumbbell Side Lateral Raise | D27: =IF('Workout Setup'!D27=0,"",'Workout Setup'!D27) -> 3 | E27: =IF('Workout Setup'!E27=0,"",'Workout Setup'!E27) -> 8 - 12 | F27: =IF('Workout Setup'!F27=0,"",'Workout Setup'!F27) -> 30 | G27: ='Workout Setup'!G27 -> 0 | I27: =IF(H27*G27=0,"",H27*G27) | J27: =IF('Workout Setup'!H27=0,"",'Workout Setup'!H27)
B28: =IF('Workout Setup'!B28=0,"",'Workout Setup'!B28) -> Shoulders | C28: =IF('Workout Setup'!C28=0,"",'Workout Setup'!C28) -> Dumbbell Seated Shoulder Press | D28: =IF('Workout Setup'!D28=0,"",'Workout Setup'!D28) -> 3 | E28: =IF('Workout Setup'!E28=0,"",'Workout Setup'!E28) -> 8 - 12 | F28: =IF('Workout Setup'!F28=0,"",'Workout Setup'!F28) -> 30 | G28: ='Workout Setup'!G28 -> 0 | I28: =IF(H28*G28=0,"",H28*G28) | J28: =IF('Workout Setup'!H28=0,"",'Workout Setup'!H28)
B29: =IF('Workout Setup'!B29=0,"",'Workout Setup'!B29) -> Shoulders | C29: =IF('Workout Setup'!C29=0,"",'Workout Setup'!C29) -> Dumbbell Front Raise | D29: =IF('Workout Setup'!D29=0,"",'Workout Setup'!D29) -> 3 | E29: =IF('Workout Setup'!E29=0,"",'Workout Setup'!E29) -> 8 - 12 | F29: =IF('Workout Setup'!F29=0,"",'Workout Setup'!F29) -> 30 | G29: ='Workout Setup'!G29 -> 0 | I29: =IF(H29*G29=0,"",H29*G29) | J29: =IF('Workout Setup'!H29=0,"",'Workout Setup'!H29)
B30: =IF('Workout Setup'!B30=0,"",'Workout Setup'!B30) -> Chest | C30: =IF('Workout Setup'!C30=0,"",'Workout Setup'!C30) -> Machine Chest Press | D30: =IF('Workout Setup'!D30=0,"",'Workout Setup'!D30) -> 3 | E30: =IF('Workout Setup'!E30=0,"",'Workout Setup'!E30) -> 8 - 12 | F30: =IF('Workout Setup'!F30=0,"",'Workout Setup'!F30) -> 30 | G30: ='Workout Setup'!G30 -> 0 | I30: =IF(H30*G30=0,"",H30*G30) | J30: =IF('Workout Setup'!H30=0,"",'Workout Setup'!H30)
B31: =IF('Workout Setup'!B31=0,"",'Workout Setup'!B31) -> Chest | C31: =IF('Workout Setup'!C31=0,"",'Workout Setup'!C31) -> Weighted Dip (Chest Variation) | D31: =IF('Workout Setup'!D31=0,"",'Workout Setup'!D31) -> 3 | E31: =IF('Workout Setup'!E31=0,"",'Workout Setup'!E31) -> 8 - 12 | F31: =IF('Workout Setup'!F31=0,"",'Workout Setup'!F31) -> 30 | G31: ='Workout Setup'!G31 -> 0 | I31: =IF(H31*G31=0,"",H31*G31) | J31: =IF('Workout Setup'!H31=0,"",'Workout Setup'!H31)
A34: Day 4 | B34: Muscle Group | C34: Exercise | D34: Sets | E34: Reps | F34: Rest (Seconds) | G34: Weight | H34: Total Reps | I34: Volume | J34: Notes
B35: =IF('Workout Setup'!B35=0,"",'Workout Setup'!B35) -> Glutes_Hamstrings | C35: =IF('Workout Setup'!C35=0,"",'Workout Setup'!C35) -> Banded Leg Extension | D35: =IF('Workout Setup'!D35=0,"",'Workout Setup'!D35) -> 3 | E35: =IF('Workout Setup'!E35=0,"",'Workout Setup'!E35) -> 20 - 25 | F35: =IF('Workout Setup'!F35=0,"",'Workout Setup'!F35) -> 30 | G35: ='Workout Setup'!G35 -> 0 | I35: =IF(H35*G35=0,"",H35*G35) | J35: =IF('Workout Setup'!H35=0,"",'Workout Setup'!H35)
B36: =IF('Workout Setup'!B36=0,"",'Workout Setup'!B36) -> Quadriceps | C36: =IF('Workout Setup'!C36=0,"",'Workout Setup'!C36) -> Dumbbell Goblet Squat | D36: =IF('Workout Setup'!D36=0,"",'Workout Setup'!D36) -> 3 | E36: =IF('Workout Setup'!E36=0,"",'Workout Setup'!E36) -> 8 - 10 | F36: =IF('Workout Setup'!F36=0,"",'Workout Setup'!F36) -> 30 | G36: ='Workout Setup'!G36 -> 0 | I36: =IF(H36*G36=0,"",H36*G36) | J36: =IF('Workout Setup'!H36=0,"",'Workout Setup'!H36)
B37: =IF('Workout Setup'!B37=0,"",'Workout Setup'!B37) -> Quadriceps | C37: =IF('Workout Setup'!C37=0,"",'Workout Setup'!C37) -> Hip Ab/Adduction (Pulse) | D37: =IF('Workout Setup'!D37=0,"",'Workout Setup'!D37) -> 3 | E37: =IF('Workout Setup'!E37=0,"",'Workout Setup'!E37) -> 6 - 8 | F37: =IF('Workout Setup'!F37=0,"",'Workout Setup'!F37) -> 30 | G37: ='Workout Setup'!G37 -> 0 | I37: =IF(H37*G37=0,"",H37*G37) | J37: =IF('Workout Setup'!H37=0,"",'Workout Setup'!H37)
B38: =IF('Workout Setup'!B38=0,"",'Workout Setup'!B38) -> Other | C38: =IF('Workout Setup'!C38=0,"",'Workout Setup'!C38) -> ITB release via Foam roller | D38: =IF('Workout Setup'!D38=0,"",'Workout Setup'!D38) -> 3 | E38: =IF('Workout Setup'!E38=0,"",'Workout Setup'!E38) -> 8 - 12 | F38: =IF('Workout Setup'!F38=0,"",'Workout Setup'!F38) -> 30 | G38: ='Workout Setup'!G38 -> 0 | I38: =IF(H38*G38=0,"",H38*G38) | J38: =IF('Workout Setup'!H38=0,"",'Workout Setup'!H38)
B39: =IF('Workout Setup'!B39=0,"",'Workout Setup'!B39) -> Other | C39: =IF('Workout Setup'!C39=0,"",'Workout Setup'!C39) -> TFL release via Trigger ball | D39: =IF('Workout Setup'!D39=0,"",'Workout Setup'!D39) -> 3 | E39: =IF('Workout Setup'!E39=0,"",'Workout Setup'!E39) -> 8 - 12 | F39: =IF('Workout Setup'!F39=0,"",'Workout Setup'!F39) -> 30 | G39: ='Workout Setup'!G39 -> 0 | I39: =IF(H39*G39=0,"",H39*G39) | J39: =IF('Workout Setup'!H39=0,"",'Workout Setup'!H39)
B40: =IF('Workout Setup'!B40=0,"",'Workout Setup'!B40) -> Calves | C40: =IF('Workout Setup'!C40=0,"",'Workout Setup'!C40) -> Single Leg Seated Calf Raise | D40: =IF('Workout Setup'!D40=0,"",'Workout Setup'!D40) -> 3 | E40: =IF('Workout Setup'!E40=0,"",'Workout Setup'!E40) -> 12 - 15 | F40: =IF('Workout Setup'!F40=0,"",'Workout Setup'!F40) -> 30 | G40: ='Workout Setup'!G40 -> 0 | I40: =IF(H40*G40=0,"",H40*G40) | J40: =IF('Workout Setup'!H40=0,"",'Workout Setup'!H40)
B41: =IF('Workout Setup'!B41=0,"",'Workout Setup'!B41) -> Calves | C41: =IF('Workout Setup'!C41=0,"",'Workout Setup'!C41) -> Machine Calf Raise | D41: =IF('Workout Setup'!D41=0,"",'Workout Setup'!D41) -> 3 | E41: =IF('Workout Setup'!E41=0,"",'Workout Setup'!E41) -> 12 - 15 | F41: =IF('Workout Setup'!F41=0,"",'Workout Setup'!F41) -> 30 | G41: ='Workout Setup'!G41 -> 0 | I41: =IF(H41*G41=0,"",H41*G41) | J41: =IF('Workout Setup'!H41=0,"",'Workout Setup'!H41)
B42: =IF('Workout Setup'!B42=0,"",'Workout Setup'!B42) -> Glutes_Hamstrings | C42: =IF('Workout Setup'!C42=0,"",'Workout Setup'!C42) -> Double Leg Hamstring Bridge | D42: =IF('Workout Setup'!D42=0,"",'Workout Setup'!D42) -> 3 | E42: =IF('Workout Setup'!E42=0,"",'Workout Setup'!E42) -> 15 - 20 | F42: =IF('Workout Setup'!F42=0,"",'Workout Setup'!F42) -> 30 | G42: ='Workout Setup'!G42 -> 0 | I42: =IF(H42*G42=0,"",H42*G42) | J42: =IF('Workout Setup'!H42=0,"",'Workout Setup'!H42)

Sheet Week 2
A1: Day 1 | B1: Muscle Group | C1: Exercise | D1: Sets | E1: Reps | F1: Rest (Seconds) | G1: Weight | H1: Total Reps | I1: Volume | J1: Note
B2: =IF('Week 1'!B2=0,"",'Week 1'!B2) -> Glutes_Hamstrings | C2: =IF('Week 1'!C2=0,"",'Week 1'!C2) -> Barbell Glute Bridge | D2: =IF('Week 1'!D2=0,"",'Week 1'!D2) -> 3 | E2: =IF('Week 1'!E2=0,"",'Week 1'!E2) -> 8 - 12 | F2: =IF('Week 1'!F2=0,"",'Week 1'!F2) -> 30 | G2: ='Week 1'!G2 -> 0 | H2: ='Week 1'!H2 -> 0 | I2: =IF(H2*G2=0,"",H2*G2) | J2: =IF('Week 1'!J2=0,"",'Week 1'!J2)
B3: =IF('Week 1'!B3=0,"",'Week 1'!B3) -> Glutes_Hamstrings | C3: =IF('Week 1'!C3=0,"",'Week 1'!C3) -> Barbell Hip Thrust | D3: =IF('Week 1'!D3=0,"",'Week 1'!D3) -> 3 | E3: =IF('Week 1'!E3=0,"",'Week 1'!E3) -> 8 - 12 | F3: =IF('Week 1'!F3=0,"",'Week 1'!F3) -> 30 | G3: ='Week 1'!G3 -> 0 | H3: ='Week 1'!H3 -> 0 | I3: =IF(H3*G3=0,"",H3*G3) | J3: =IF('Week 1'!J3=0,"",'Week 1'!J3)
B4: =IF('Week 1'!B4=0,"",'Week 1'!B4) -> Glutes_Hamstrings | C4: =IF('Week 1'!C4=0,"",'Week 1'!C4) -> Cable One-Legged Kickback | D4: =IF('Week 1'!D4=0,"",'Week 1'!D4) -> 3 | E4: =IF('Week 1'!E4=0,"",'Week 1'!E4) -> 8 - 12 | F4: =IF('Week 1'!F4=0,"",'Week 1'!F4) -> 30 | G4: ='Week 1'!G4 -> 0 | H4: ='Week 1'!H4 -> 0 | I4: =IF(H4*G4=0,"",H4*G4) | J4: =IF('Week 1'!J4=0,"",'Week 1'!J4)
B5: =IF('Week 1'!B5=0,"",'Week 1'!B5) -> Quadriceps | C5: =IF('Week 1'!C5=0,"",'Week 1'!C5) -> Barbell Squat | D5: =IF('Week 1'!D5=0,"",'Week 1'!D5) -> 3 | E5: =IF('Week 1'!E5=0,"",'Week 1'!E5) -> 8 - 12 | F5: =IF('Week 1'!F5=0,"",'Week 1'!F5) -> 30 | G5: ='Week 1'!G5 -> 0 | H5: ='Week 1'!H5 -> 0 | I5: =IF(H5*G5=0,"",H5*G5) | J5: =IF('Week 1'!J5=0,"",'Week 1'!J5)
B6: =IF('Week 1'!B6=0,"",'Week 1'!B6) -> Quadriceps | C6: =IF('Week 1'!C6=0,"",'Week 1'!C6) -> Machine Laying Leg Press | D6: =IF('Week 1'!D6=0,"",'Week 1'!D6) -> 3 | E6: =IF('Week 1'!E6=0,"",'Week 1'!E6) -> 8 - 12 | F6: =IF('Week 1'!F6=0,"",'Week 1'!F6) -> 30 | G6: ='Week 1'!G6 -> 0 | H6: ='Week 1'!H6 -> 0 | I6: =IF(H6*G6=0,"",H6*G6) | J6: =IF('Week 1'!J6=0,"",'Week 1'!J6)
B7: =IF('Week 1'!B7=0,"",'Week 1'!B7) -> Quadriceps | C7: =IF('Week 1'!C7=0,"",'Week 1'!C7) -> Body Weight Bulgarian Split-Squat | D7: =IF('Week 1'!D7=0,"",'Week 1'!D7) -> 3 | E7: =IF('Week 1'!E7=0,"",'Week 1'!E7) -> 8 - 12 | F7: =IF('Week 1'!F7=0,"",'Week 1'!F7) -> 30 | G7: ='Week 1'!G7 -> 0 | H7: ='Week 1'!H7 -> 0 | I7: =IF(H7*G7=0,"",H7*G7) | J7: =IF('Week 1'!J7=0,"",'Week 1'!J7)
B8: =IF('Week 1'!B8=0,"",'Week 1'!B8) -> Calves | C8: =IF('Week 1'!C8=0,"",'Week 1'!C8) -> Dumbbell Calf Raise | D8: =IF('Week 1'!D8=0,"",'Week 1'!D8) -> 3 | E8: =IF('Week 1'!E8=0,"",'Week 1'!E8) -> 15 - 20 | F8: =IF('Week 1'!F8=0,"",'Week 1'!F8) -> 30 | G8: ='Week 1'!G8 -> 0 | H8: ='Week 1'!H8 -> 0 | I8: =IF(H8*G8=0,"",H8*G8) | J8: =IF('Week 1'!J8=0,"",'Week 1'!J8)
B9: =IF('Week 1'!B9=0,"",'Week 1'!B9) -> Quadriceps | C9: =IF('Week 1'!C9=0,"",'Week 1'!C9) -> Machine Calf Raise | D9: =IF('Week 1'!D9=0,"",'Week 1'!D9) -> 3 | E9: =IF('Week 1'!E9=0,"",'Week 1'!E9) -> 15 - 20 | F9: =IF('Week 1'!F9=0,"",'Week 1'!F9) -> 30 | G9: ='Week 1'!G9 -> 0 | H9: ='Week 1'!H9 -> 0 | I9: =IF(H9*G9=0,"",H9*G9) | J9: =IF('Week 1'!J9=0,"",'Week 1'!J9)
A12: Day 2 | B12: Muscle Group | C12: Exercise | D12: Sets | E12: Reps | F12: Rest (Seconds) | G12: Weight | H12: Total Reps | I12: Volume | J12: Note
B13: =IF('Week 1'!B13=0,"",'Week 1'!B13) -> Back | C13: =IF('Week 1'!C13=0,"",'Week 1'!C13) -> Cable Narrow-Grip Lat Pull-Down | D13: =IF('Week 1'!D13=0,"",'Week 1'!D13) -> 3 | E13: =IF('Week 1'!E13=0,"",'Week 1'!E13) -> 8 - 12 | F13: =IF('Week 1'!F13=0,"",'Week 1'!F13) -> 30 | G13: ='Week 1'!G13 -> 0 | H13: ='Week 1'!H13 -> 0 | I13: =IF(H13*G13=0,"",H13*G13) | J13: =IF('Week 1'!J13=0,"",'Week 1'!J13)
B14: =IF('Week 1'!B14=0,"",'Week 1'!B14) -> Back | C14: =IF('Week 1'!C14=0,"",'Week 1'!C14) -> Cable Wide-Grip Lat Pull-Down | D14: =IF('Week 1'!D14=0,"",'Week 1'!D14) -> 3 | E14: =IF('Week 1'!E14=0,"",'Week 1'!E14) -> 8 - 12 | F14: =IF('Week 1'!F14=0,"",'Week 1'!F14) -> 30 | G14: ='Week 1'!G14 -> 0 | H14: ='Week 1'!H14 -> 0 | I14: =IF(H14*G14=0,"",H14*G14) | J14: =IF(#REF!=0,"",#REF!) -> #REF!
B15: =IF('Week 1'!B15=0,"",'Week 1'!B15) -> Back | C15: =IF('Week 1'!C15=0,"",'Week 1'!C15) -> Machine Back Extension | D15: =IF('Week 1'!D15=0,"",'Week 1'!D15) -> 3 | E15: =IF('Week 1'!E15=0,"",'Week 1'!E15) -> 8 - 12 | F15: =IF('Week 1'!F15=0,"",'Week 1'!F15) -> 30 | G15: ='Week 1'!G15 -> 0 | H15: ='Week 1'!H15 -> 0 | I15: =IF(H15*G15=0,"",H15*G15) | J15: =IF('Week 1'!J15=0,"",'Week 1'!J15)
B16: =IF('Week 1'!B16=0,"",'Week 1'!B16) -> Triceps | C16: =IF('Week 1'!C16=0,"",'Week 1'!C16) -> Body Weight Bench Dip | D16: =IF('Week 1'!D16=0,"",'Week 1'!D16) -> 3 | E16: =IF('Week 1'!E16=0,"",'Week 1'!E16) -> 8 - 12 | F16: =IF('Week 1'!F16=0,"",'Week 1'!F16) -> 30 | G16: ='Week 1'!G16 -> 0 | H16: ='Week 1'!H16 -> 0 | I16: =IF(H16*G16=0,"",H16*G16) | J16: =IF('Week 1'!J16=0,"",'Week 1'!J16)
B17: =IF('Week 1'!B17=0,"",'Week 1'!B17) -> Triceps | C17: =IF('Week 1'!C17=0,"",'Week 1'!C17) -> Cable Overhead Triceps Extension | D17: =IF('Week 1'!D17=0,"",'Week 1'!D17) -> 3 | E17: =IF('Week 1'!E17=0,"",'Week 1'!E17) -> 8 - 12 | F17: =IF('Week 1'!F17=0,"",'Week 1'!F17) -> 30 | G17: ='Week 1'!G17 -> 0 | H17: ='Week 1'!H17 -> 0 | I17: =IF(H17*G17=0,"",H17*G17) | J17: =IF('Week 1'!J17=0,"",'Week 1'!J17)
B18: =IF('Week 1'!B18=0,"",'Week 1'!B18) -> Triceps | C18: =IF('Week 1'!C18=0,"",'Week 1'!C18) -> Machine Triceps Extension | D18: =IF('Week 1'!D18=0,"",'Week 1'!D18) -> 3 | E18: =IF('Week 1'!E18=0,"",'Week 1'!E18) -> 8 - 12 | F18: =IF('Week 1'!F18=0,"",'Week 1'!F18) -> 30 | G18: ='Week 1'!G18 -> 0 | H18: ='Week 1'!H18 -> 0 | I18: =IF(H18*G18=0,"",H18*G18) | J18: =IF('Week 1'!J18=0,"",'Week 1'!J18)
B19: =IF('Week 1'!B19=0,"",'Week 1'!B19) -> Abs | C19: =IF('Week 1'!C19=0,"",'Week 1'!C19) -> Body Weight Hanging Leg Raise | D19: =IF('Week 1'!D19=0,"",'Week 1'!D19) -> 3 | E19: =IF('Week 1'!E19=0,"",'Week 1'!E19) -> 15 - 20 | F19: =IF('Week 1'!F19=0,"",'Week 1'!F19) -> 30 | G19: ='Week 1'!G19 -> 0 | H19: ='Week 1'!H19 -> 0 | I19: =IF(H19*G19=0,"",H19*G19) | J19: =IF('Week 1'!J19=0,"",'Week 1'!J19)
B20: =IF('Week 1'!B20=0,"",'Week 1'!B20) -> Abs | C20: =IF('Week 1'!C20=0,"",'Week 1'!C20) -> Body Weight Ab Crunch | D20: =IF('Week 1'!D20=0,"",'Week 1'!D20) -> 3 | E20: =IF('Week 1'!E20=0,"",'Week 1'!E20) -> 15 - 20 | F20: =IF('Week 1'!F20=0,"",'Week 1'!F20) -> 30 | G20: ='Week 1'!G20 -> 0 | H20: ='Week 1'!H20 -> 0 | I20: =IF(H20*G20=0,"",H20*G20) | J20: =IF('Week 1'!J20=0,"",'Week 1'!J20)
A23: Day 3 | B23: Muscle Group | C23: Exercise | D23: Sets | E23: Reps | F23: Rest (Seconds) | G23: Weight | H23: Total Reps | I23: Volume | J23: Note
B24: =IF('Week 1'!B24=0,"",'Week 1'!B24) -> Biceps | C24: =IF('Week 1'!C24=0,"",'Week 1'!C24) -> Dumbbell Hammer Biceps Curl | D24: =IF('Week 1'!D24=0,"",'Week 1'!D24) -> 3 | E24: =IF('Week 1'!E24=0,"",'Week 1'!E24) -> 8 - 12 | F24: =IF('Week 1'!F24=0,"",'Week 1'!F24) -> 30 | G24: ='Week 1'!G24 -> 0 | H24: ='Week 1'!H24 -> 0 | I24: =IF(H24*G24=0,"",H24*G24) | J24: =IF('Week 1'!J24=0,"",'Week 1'!J24)
B25: =IF('Week 1'!B25=0,"",'Week 1'!B25) -> Biceps | C25: =IF('Week 1'!C25=0,"",'Week 1'!C25) -> Dumbbell Incline Bench Biceps Curl | D25: =IF('Week 1'!D25=0,"",'Week 1'!D25) -> 3 | E25: =IF('Week 1'!E25=0,"",'Week 1'!E25) -> 8 - 12 | F25: =IF('Week 1'!F25=0,"",'Week 1'!F25) -> 30 | G25: ='Week 1'!G25 -> 0 | H25: ='Week 1'!H25 -> 0 | I25: =IF(H25*G25=0,"",H25*G25) | J25: =IF('Week 1'!J25=0,"",'Week 1'!J25)
B26: =IF('Week 1'!B26=0,"",'Week 1'!B26) -> Biceps | C26: =IF('Week 1'!C26=0,"",'Week 1'!C26) -> Barbell Preacher Biceps Curl | D26: =IF('Week 1'!D26=0,"",'Week 1'!D26) -> 3 | E26: =IF('Week 1'!E26=0,"",'Week 1'!E26) -> 8 - 12 | F26: =IF('Week 1'!F26=0,"",'Week 1'!F26) -> 30 | G26: ='Week 1'!G26 -> 0 | H26: ='Week 1'!H26 -> 0 | I26: =IF(H26*G26=0,"",H26*G26) | J26: =IF('Week 1'!J26=0,"",'Week 1'!J26)
